Workbook

Sheet native_pivots
A1: Native pivot tables
A2: Pivot tables use calc_lines as their source and can be refreshed in Excel.
B4: 值 | G4: 值
A5: 行标签 | B5: Net receivable | C5: Gross amount | F5: 行标签 | G5: Delivered quantity | H5: Returned quantity
A6: 模拟_桥头家常菜馆 | B6: 6594.59 | C6: 6605.22 | F6: 白萝卜 | G6: 384.9 | H6: 0
A7: 模拟_青禾小学食堂 | B7: 11237.09 | C7: 11237.95 | F7: 公斤 | G7: 384.9 | H7: 0
A8: 模拟_榕树下粉面店 | B8: 2765.55 | C8: 2775.04 | F8: 包菜 | G8: 440 | H8: 0
A9: 模拟_田畔饭店 | B9: 3894.01 | C9: 3896.34 | F9: 公斤 | G9: 440 | H9: 0
A10: 模拟_溪桥医院食堂 | B10: 10886.34 | C10: 10892.4 | F10: 菜籽油 | G10: 15 | H10: 0
A11: 模拟_兴街快餐店 | B11: 9536.72 | C11: 9545.09 | F11: 桶 | G11: 15 | H11: 0
A12: 总计 | B12: 44914.3 | C12: 44952.04 | F12: 大豆油 | G12: 34 | H12: 0
F13: 桶 | G13: 34 | H13: 0
F14: 冬瓜 | G14: 392.6 | H14: 0
F15: 公斤 | G15: 392.6 | H15: 0
F16: 红薯叶 | G16: 343.6 | H16: 3
F17: 公斤 | G17: 343.6 | H17: 3
F18: 黄瓜 | G18: 453.8 | H18: 0
F19: 公斤 | G19: 453.8 | H19: 0
F20: 鸡蛋 | G20: 470.5 | H20: 0.4
F21: 公斤 | G21: 470.5 | H21: 0.4
F22: 豇豆 | G22: 427.3 | H22: 0
F23: 公斤 | G23: 427.3 | H23: 0
F24: 空心菜 | G24: 274.7 | H24: 1.2
B25: 值 | F25: 公斤 | G25: 274.7 | H25: 1.2
A26: 行标签 | B26: Ordered quantity | C26: Delivered quantity | F26: 南瓜 | G26: 376 | H26: 0
A27: 46266 | B27: 311.6 | C27: 310.6 | F27: 公斤 | G27: 376 | H27: 0
A28: 46267 | B28: 190.5 | C28: 190.5 | F28: 茄子 | G28: 447.4 | H28: 0
A29: 46268 | B29: 257.7 | C29: 256.3 | F29: 公斤 | G29: 447.4 | H29: 0
A30: 46269 | B30: 204 | C30: 203.8 | F30: 青椒 | G30: 381 | H30: 0
A31: 46270 | B31: 213.7 | C31: 212.7 | F31: 公斤 | G31: 381 | H31: 0
A32: 46271 | B32: 88.6 | C32: 88.6 | F32: 丝瓜 | G32: 377 | H32: 0
A33: 46272 | B33: 196.4 | C33: 195.9 | F33: 公斤 | G33: 377 | H33: 0
A34: 46273 | B34: 247.6 | C34: 247.1 | F34: 土豆 | G34: 443 | H34: 0
A35: 46274 | B35: 205.8 | C35: 205.6 | F35: 公斤 | G35: 443 | H35: 0
A36: 46275 | B36: 235.7 | C36: 235 | F36: 西红柿 | G36: 421.3 | H36: 0
A37: 46276 | B37: 233.8 | C37: 233.5 | F37: 公斤 | G37: 421.3 | H37: 0
A38: 46277 | B38: 200.3 | C38: 199.8 | F38: 籼米 | G38: 111 | H38: 0
... A46: 46285 | B46: 171.4 | C46: 171.1 | F46: 总计 | G46: 6203 | H46: 7.5
A47: 46286 | B47: 187.4 | C47: 186.2
A48: 46287 | B48: 263.4 | C48: 262.9
...

Sheet checklist
A1: 生鲜批发订单与对账核对页
A2: Excel 公式路径与 Python、SQLite 结果逐项对拍；截止日可编辑
A4: 对账截止日 | B4: 46301
A5: 金额口径 | B5: 交付金额、退货金额分别 ROUND 到分后相减
A7: 核对项 | B7: Excel | C7: 独立参考 | D7: 差异 | E7: 状态
A8: 明细行数 | B8: =COUNTA(calc_lines!$A$2:$A$967) -> 966 | C8: 966 | D8: =B8-C8 -> 0 | E8: =IF(ABS(D8)<0.005,"一致","差异") -> 一致
A9: 订单数 | B9: =COUNTIFS(calc_orders!$J$2:$J$144,"<>暂缓") -> 143 | C9: 143 | D9: =B9-C9 -> 0 | E9: =IF(ABS(D9)<0.005,"一致","差异") -> 一致
A10: 9 月净应收 | B10: =SUM(calc_customers!$D$2:$D$7) -> 44914.3 | C10: 44914.3 | D10: =B10-C10 -> 0 | E10: =IF(ABS(D10)<0.005,"一致","差异") -> 一致
A11: 截止日已收 | B11: =SUM(calc_customers!$E$2:$E$7) -> 26254.15 | C11: 26254.15 | D11: =B11-C11 -> 0 | E11: =IF(ABS(D11)<0.005,"一致","差异") -> 一致
A12: 截止日未结清 | B12: =SUM(calc_customers!$F$2:$F$7) -> 18660.15 | C12: 18660.15 | D12: =B12-C12 -> 0 | E12: =IF(ABS(D12)<0.005,"一致","差异") -> 一致
A13: 09-30 已收 | B13: =SUMIFS(fact_payments!$D$2:$D$101,fact_payments!$C$2:$C$101,"<="&DATE(2026,9,30)) -> 6000 | C13: 6000 | D13: =B13-C13 -> 0 | E13: =IF(ABS(D13)<0.005,"一致","差异") -> 一致
A14: 数据质量异常 | B14: =COUNTIF(calc_lines!$W$2:$W$967,"阻断")+COUNTIF(calc_lines!$W$2:$W$967,"提示") -> 0 | C14: 0 | D14: =B14-C14 -> 0 | E14: =IF(ABS(D14)<0.005,"一致","差异") -> 一致
A16: 截止日外回款（口径排除） | B16: =COUNTIF(fact_payments!$C$2:$C$101,">"&$B$4) -> 0
A17: 暂缓订单 | B17: =COUNTIF(calc_orders!$J$2:$J$144,"暂缓") -> 0
A18: 抽样订单 SIM-20260901-C001 | B18: =INDEX(calc_orders!$G$2:$G$144,MATCH("SIM-20260901-C001",calc_orders!$A$2:$A$144,0)) -> 256.6
A19: 抽样订单状态 | B19: =INDEX(calc_orders!$J$2:$J$144,MATCH("SIM-20260901-C001",calc_orders!$A$2:$A$144,0)) -> 已结清

Sheet calc_customers
A1: customer_id | B1: customer_name | C1: order_count | D1: net_receivable | E1: received | F1: balance | G1: status
A2: C001 | B2: =INDEX(dim_customers!$B$2:$B$7,MATCH($A2,dim_customers!$A$2:$A$7,0)) -> 模拟_榕树下粉面店 | C2: =COUNTIFS(calc_orders!$B$2:$B$144,$A2,calc_orders!$J$2:$J$144,"<>暂缓") -> 26 | D2: =SUMIFS(calc_orders!$G$2:$G$144,calc_orders!$B$2:$B$144,$A2,calc_orders!$J$2:$J$144,"<>暂缓") -> 2765.55 | E2: =SUMIFS(calc_orders!$H$2:$H$144,calc_orders!$B$2:$B$144,$A2,calc_orders!$J$2:$J$144,"<>暂缓") -> 2765.55 | F2: =$D2-$E2 -> 0 | G2: =IF($F2=0,"已结清","未结清") -> 已结清
A3: C002 | B3: =INDEX(dim_customers!$B$2:$B$7,MATCH($A3,dim_customers!$A$2:$A$7,0)) -> 模拟_桥头家常菜馆 | C3: =COUNTIFS(calc_orders!$B$2:$B$144,$A3,calc_orders!$J$2:$J$144,"<>暂缓") -> 26 | D3: =SUMIFS(calc_orders!$G$2:$G$144,calc_orders!$B$2:$B$144,$A3,calc_orders!$J$2:$J$144,"<>暂缓") -> 6594.59 | E3: =SUMIFS(calc_orders!$H$2:$H$144,calc_orders!$B$2:$B$144,$A3,calc_orders!$J$2:$J$144,"<>暂缓") -> 6594.59 | F3: =$D3-$E3 -> 0 | G3: =IF($F3=0,"已结清","未结清") -> 已结清
A4: C003 | B4: =INDEX(dim_customers!$B$2:$B$7,MATCH($A4,dim_customers!$A$2:$A$7,0)) -> 模拟_兴街快餐店 | C4: =COUNTIFS(calc_orders!$B$2:$B$144,$A4,calc_orders!$J$2:$J$144,"<>暂缓") -> 26 | D4: =SUMIFS(calc_orders!$G$2:$G$144,calc_orders!$B$2:$B$144,$A4,calc_orders!$J$2:$J$144,"<>暂缓") -> 9536.72 | E4: =SUMIFS(calc_orders!$H$2:$H$144,calc_orders!$B$2:$B$144,$A4,calc_orders!$J$2:$J$144,"<>暂缓") -> 3000 | F4: =$D4-$E4 -> 6536.72 | G4: =IF($F4=0,"已结清","未结清") -> 未结清
A5: C004 | B5: =INDEX(dim_customers!$B$2:$B$7,MATCH($A5,dim_customers!$A$2:$A$7,0)) -> 模拟_田畔饭店 | C5: =COUNTIFS(calc_orders!$B$2:$B$144,$A5,calc_orders!$J$2:$J$144,"<>暂缓") -> 13 | D5: =SUMIFS(calc_orders!$G$2:$G$144,calc_orders!$B$2:$B$144,$A5,calc_orders!$J$2:$J$144,"<>暂缓") -> 3894.01 | E5: =SUMIFS(calc_orders!$H$2:$H$144,calc_orders!$B$2:$B$144,$A5,calc_orders!$J$2:$J$144,"<>暂缓") -> 3894.01 | F5: =$D5-$E5 -> 0 | G5: =IF($F5=0,"已结清","未结清") -> 已结清
A6: C005 | B6: =INDEX(dim_customers!$B$2:$B$7,MATCH($A6,dim_customers!$A$2:$A$7,0)) -> 模拟_青禾小学食堂 | C6: =COUNTIFS(calc_orders!$B$2:$B$144,$A6,calc_orders!$J$2:$J$144,"<>暂缓") -> 22 | D6: =SUMIFS(calc_orders!$G$2:$G$144,calc_orders!$B$2:$B$144,$A6,calc_orders!$J$2:$J$144,"<>暂缓") -> 11237.09 | E6: =SUMIFS(calc_orders!$H$2:$H$144,calc_orders!$B$2:$B$144,$A6,calc_orders!$J$2:$J$144,"<>暂缓") -> 5000 | F6: =$D6-$E6 -> 6237.09 | G6: =IF($F6=0,"已结清","未结清") -> 未结清
A7: C006 | B7: =INDEX(dim_customers!$B$2:$B$7,MATCH($A7,dim_customers!$A$2:$A$7,0)) -> 模拟_溪桥医院食堂 | C7: =COUNTIFS(calc_orders!$B$2:$B$144,$A7,calc_orders!$J$2:$J$144,"<>暂缓") -> 30 | D7: =SUMIFS(calc_orders!$G$2:$G$144,calc_orders!$B$2:$B$144,$A7,calc_orders!$J$2:$J$144,"<>暂缓") -> 10886.34 | E7: =SUMIFS(calc_orders!$H$2:$H$144,calc_orders!$B$2:$B$144,$A7,calc_orders!$J$2:$J$144,"<>暂缓") -> 5000 | F7: =$D7-$E7 -> 5886.34 | G7: =IF($F7=0,"已结清","未结清") -> 未结清

Sheet calc_orders
A1: order_id | B1: customer_id | C1: customer_name | D1: order_date | E1: line_count | F1: blocked_line_count | G1: net_receivable | H1: received | I1: balance | J1: status
A2: SIM-20260901-C001 | B2: =INDEX(calc_lines!$C$2:$C$967,MATCH($A2,calc_lines!$A$2:$A$967,0)) -> C001 | C2: =INDEX(calc_lines!$O$2:$O$967,MATCH($A2,calc_lines!$A$2:$A$967,0)) -> 模拟_榕树下粉面店 | D2: =INDEX(calc_lines!$D$2:$D$967,MATCH($A2,calc_lines!$A$2:$A$967,0)) -> 46266 | E2: =COUNTIF(calc_lines!$A$2:$A$967,$A2) -> 8 | F2: =COUNTIFS(calc_lines!$A$2:$A$967,$A2,calc_lines!$W$2:$W$967,"阻断") -> 0 | G2: =IF($F2>0,"",ROUND(SUMIF(calc_lines!$A$2:$A$967,$A2,calc_lines!$R$2:$R$967),2)) -> 256.6 | H2: =IF($F2>0,"",ROUND(SUMIFS(fact_payments!$D$2:$D$101,fact_payments!$B$2:$B$101,$A2,fact_payments!$C$2:$C$101,"<="&checklist!$B$4),2)) -> 256.6 | I2: =IF($F2>0,"",$G2-$H2) -> 0 | J2: =IF($F2>0,"暂缓",IF($I2=0,"已结清","未结清")) -> 已结清
A3: SIM-20260901-C002 | B3: =INDEX(calc_lines!$C$2:$C$967,MATCH($A3,calc_lines!$A$2:$A$967,0)) -> C002 | C3: =INDEX(calc_lines!$O$2:$O$967,MATCH($A3,calc_lines!$A$2:$A$967,0)) -> 模拟_桥头家常菜馆 | D3: =INDEX(calc_lines!$D$2:$D$967,MATCH($A3,calc_lines!$A$2:$A$967,0)) -> 46266 | E3: =COUNTIF(calc_lines!$A$2:$A$967,$A3) -> 9 | F3: =COUNTIFS(calc_lines!$A$2:$A$967,$A3,calc_lines!$W$2:$W$967,"阻断") -> 0 | G3: =IF($F3>0,"",ROUND(SUMIF(calc_lines!$A$2:$A$967,$A3,calc_lines!$R$2:$R$967),2)) -> 598.22 | H3: =IF($F3>0,"",ROUND(SUMIFS(fact_payments!$D$2:$D$101,fact_payments!$B$2:$B$101,$A3,fact_payments!$C$2:$C$101,"<="&checklist!$B$4),2)) -> 598.22 | I3: =IF($F3>0,"",$G3-$H3) -> 0 | J3: =IF($F3>0,"暂缓",IF($I3=0,"已结清","未结清")) -> 已结清
A4: SIM-20260901-C003 | B4: =INDEX(calc_lines!$C$2:$C$967,MATCH($A4,calc_lines!$A$2:$A$967,0)) -> C003 | C4: =INDEX(calc_lines!$O$2:$O$967,MATCH($A4,calc_lines!$A$2:$A$967,0)) -> 模拟_兴街快餐店 | D4: =INDEX(calc_lines!$D$2:$D$967,MATCH($A4,calc_lines!$A$2:$A$967,0)) -> 46266 | E4: =COUNTIF(calc_lines!$A$2:$A$967,$A4) -> 10 | F4: =COUNTIFS(calc_lines!$A$2:$A$967,$A4,calc_lines!$W$2:$W$967,"阻断") -> 0 | G4: =IF($F4>0,"",ROUND(SUMIF(calc_lines!$A$2:$A$967,$A4,calc_lines!$R$2:$R$967),2)) -> 901.28 | H4: =IF($F4>0,"",ROUND(SUMIFS(fact_payments!$D$2:$D$101,fact_payments!$B$2:$B$101,$A4,fact_payments!$C$2:$C$101,"<="&checklist!$B$4),2)) -> 901.28 | I4: =IF($F4>0,"",$G4-$H4) -> 0 | J4: =IF($F4>0,"暂缓",IF($I4=0,"已结清","未结清")) -> 已结清
A5: SIM-20260901-C004 | B5: =INDEX(calc_lines!$C$2:$C$967,MATCH($A5,calc_lines!$A$2:$A$967,0)) -> C004 | C5: =INDEX(calc_lines!$O$2:$O$967,MATCH($A5,calc_lines!$A$2:$A$967,0)) -> 模拟_田畔饭店 | D5: =INDEX(calc_lines!$D$2:$D$967,MATCH($A5,calc_lines!$A$2:$A$967,0)) -> 46266 | E5: =COUNTIF(calc_lines!$A$2:$A$967,$A5) -> 10 | F5: =COUNTIFS(calc_lines!$A$2:$A$967,$A5,calc_lines!$W$2:$W$967,"阻断") -> 0 | G5: =IF($F5>0,"",ROUND(SUMIF(calc_lines!$A$2:$A$967,$A5,calc_lines!$R$2:$R$967),2)) -> 619.83 | H5: =IF($F5>0,"",ROUND(SUMIFS(fact_payments!$D$2:$D$101,fact_payments!$B$2:$B$101,$A5,fact_payments!$C$2:$C$101,"<="&checklist!$B$4),2)) -> 619.83 | I5: =IF($F5>0,"",$G5-$H5) -> 0 | J5: =IF($F5>0,"暂缓",IF($I5=0,"已结清","未结清")) -> 已结清
A6: SIM-20260901-C005 | B6: =INDEX(calc_lines!$C$2:$C$967,MATCH($A6,calc_lines!$A$2:$A$967,0)) -> C005 | C6: =INDEX(calc_lines!$O$2:$O$967,MATCH($A6,calc_lines!$A$2:$A$967,0)) -> 模拟_青禾小学食堂 | D6: =INDEX(calc_lines!$D$2:$D$967,MATCH($A6,calc_lines!$A$2:$A$967,0)) -> 46266 | E6: =COUNTIF(calc_lines!$A$2:$A$967,$A6) -> 10 | F6: =COUNTIFS(calc_lines!$A$2:$A$967,$A6,calc_lines!$W$2:$W$967,"阻断") -> 0 | G6: =IF($F6>0,"",ROUND(SUMIF(calc_lines!$A$2:$A$967,$A6,calc_lines!$R$2:$R$967),2)) -> 1212.68 | H6: =IF($F6>0,"",ROUND(SUMIFS(fact_payments!$D$2:$D$101,fact_payments!$B$2:$B$101,$A6,fact_payments!$C$2:$C$101,"<="&checklist!$B$4),2)) -> 1212.68 | I6: =IF($F6>0,"",$G6-$H6) -> 0 | J6: =IF($F6>0,"暂缓",IF($I6=0,"已结清","未结清")) -> 已结清
A7: SIM-20260901-C006 | B7: =INDEX(calc_lines!$C$2:$C$967,MATCH($A7,calc_lines!$A$2:$A$967,0)) -> C006 | C7: =INDEX(calc_lines!$O$2:$O$967,MATCH($A7,calc_lines!$A$2:$A$967,0)) -> 模拟_溪桥医院食堂 | D7: =INDEX(calc_lines!$D$2:$D$967,MATCH($A7,calc_lines!$A$2:$A$967,0)) -> 46266 | E7: =COUNTIF(calc_lines!$A$2:$A$967,$A7) -> 10 | F7: =COUNTIFS(calc_lines!$A$2:$A$967,$A7,calc_lines!$W$2:$W$967,"阻断") -> 0 | G7: =IF($F7>0,"",ROUND(SUMIF(calc_lines!$A$2:$A$967,$A7,calc_lines!$R$2:$R$967),2)) -> 926.26 | H7: =IF($F7>0,"",ROUND(SUMIFS(fact_payments!$D$2:$D$101,fact_payments!$B$2:$B$101,$A7,fact_payments!$C$2:$C$101,"<="&checklist!$B$4),2)) -> 926.26 | I7: =IF($F7>0,"",$G7-$H7) -> 0 | J7: =IF($F7>0,"暂缓",IF($I7=0,"已结清","未结清")) -> 已结清
A8: SIM-20260902-C001 | B8: =INDEX(calc_lines!$C$2:$C$967,MATCH($A8,calc_lines!$A$2:$A$967,0)) -> C001 | C8: =INDEX(calc_lines!$O$2:$O$967,MATCH($A8,calc_lines!$A$2:$A$967,0)) -> 模拟_榕树下粉面店 | D8: =INDEX(calc_lines!$D$2:$D$967,MATCH($A8,calc_lines!$A$2:$A$967,0)) -> 46267 | E8: =COUNTIF(calc_lines!$A$2:$A$967,$A8) -> 4 | F8: =COUNTIFS(calc_lines!$A$2:$A$967,$A8,calc_lines!$W$2:$W$967,"阻断") -> 0 | G8: =IF($F8>0,"",ROUND(SUMIF(calc_lines!$A$2:$A$967,$A8,calc_lines!$R$2:$R$967),2)) -> 47.9 | H8: =IF($F8>0,"",ROUND(SUMIFS(fact_payments!$D$2:$D$101,fact_payments!$B$2:$B$101,$A8,fact_payments!$C$2:$C$101,"<="&checklist!$B$4),2)) -> 47.9 | I8: =IF($F8>0,"",$G8-$H8) -> 0 | J8: =IF($F8>0,"暂缓",IF($I8=0,"已结清","未结清")) -> 已结清
A9: SIM-20260902-C002 | B9: =INDEX(calc_lines!$C$2:$C$967,MATCH($A9,calc_lines!$A$2:$A$967,0)) -> C002 | C9: =INDEX(calc_lines!$O$2:$O$967,MATCH($A9,calc_lines!$A$2:$A$967,0)) -> 模拟_桥头家常菜馆 | D9: =INDEX(calc_lines!$D$2:$D$967,MATCH($A9,calc_lines!$A$2:$A$967,0)) -> 46267 | E9: =COUNTIF(calc_lines!$A$2:$A$967,$A9) -> 5 | F9: =COUNTIFS(calc_lines!$A$2:$A$967,$A9,calc_lines!$W$2:$W$967,"阻断") -> 0 | G9: =IF($F9>0,"",ROUND(SUMIF(calc_lines!$A$2:$A$967,$A9,calc_lines!$R$2:$R$967),2)) -> 94.5 | H9: =IF($F9>0,"",ROUND(SUMIFS(fact_payments!$D$2:$D$101,fact_payments!$B$2:$B$101,$A9,fact_payments!$C$2:$C$101,"<="&checklist!$B$4),2)) -> 94.5 | I9: =IF($F9>0,"",$G9-$H9) -> 0 | J9: =IF($F9>0,"暂缓",IF($I9=0,"已结清","未结清")) -> 已结清
A10: SIM-20260902-C003 | B10: =INDEX(calc_lines!$C$2:$C$967,MATCH($A10,calc_lines!$A$2:$A$967,0)) -> C003 | C10: =INDEX(calc_lines!$O$2:$O$967,MATCH($A10,calc_lines!$A$2:$A$967,0)) -> 模拟_兴街快餐店 | D10: =INDEX(calc_lines!$D$2:$D$967,MATCH($A10,calc_lines!$A$2:$A$967,0)) -> 46267 | E10: =COUNTIF(calc_lines!$A$2:$A$967,$A10) -> 6 | F10: =COUNTIFS(calc_lines!$A$2:$A$967,$A10,calc_lines!$W$2:$W$967,"阻断") -> 0 | G10: =IF($F10>0,"",ROUND(SUMIF(calc_lines!$A$2:$A$967,$A10,calc_lines!$R$2:$R$967),2)) -> 159.16 | H10: =IF($F10>0,"",ROUND(SUMIFS(fact_payments!$D$2:$D$101,fact_payments!$B$2:$B$101,$A10,fact_payments!$C$2:$C$101,"<="&checklist!$B$4),2)) -> 159.16 | I10: =IF($F10>0,"",$G10-$H10) -> 0 | J10: =IF($F10>0,"暂缓",IF($I10=0,"已结清","未结清")) -> 已结清
A11: SIM-20260902-C005 | B11: =INDEX(calc_lines!$C$2:$C$967,MATCH($A11,calc_lines!$A$2:$A$967,0)) -> C005 | C11: =INDEX(calc_lines!$O$2:$O$967,MATCH($A11,calc_lines!$A$2:$A$967,0)) -> 模拟_青禾小学食堂 | D11: =INDEX(calc_lines!$D$2:$D$967,MATCH($A11,calc_lines!$A$2:$A$967,0)) -> 46267 | E11: =COUNTIF(calc_lines!$A$2:$A$967,$A11) -> 6 | F11: =COUNTIFS(calc_lines!$A$2:$A$967,$A11,calc_lines!$W$2:$W$967,"阻断") -> 0 | G11: =IF($F11>0,"",ROUND(SUMIF(calc_lines!$A$2:$A$967,$A11,calc_lines!$R$2:$R$967),2)) -> 253.19 | H11: =IF($F11>0,"",ROUND(SUMIFS(fact_payments!$D$2:$D$101,fact_payments!$B$2:$B$101,$A11,fact_payments!$C$2:$C$101,"<="&checklist!$B$4),2)) -> 253.19 | I11: =IF($F11>0,"",$G11-$H11) -> 0 | J11: =IF($F11>0,"暂缓",IF($I11=0,"已结清","未结清")) -> 已结清
A12: SIM-20260902-C006 | B12: =INDEX(calc_lines!$C$2:$C$967,MATCH($A12,calc_lines!$A$2:$A$967,0)) -> C006 | C12: =INDEX(calc_lines!$O$2:$O$967,MATCH($A12,calc_lines!$A$2:$A$967,0)) -> 模拟_溪桥医院食堂 | D12: =INDEX(calc_lines!$D$2:$D$967,MATCH($A12,calc_lines!$A$2:$A$967,0)) -> 46267 | E12: =COUNTIF(calc_lines!$A$2:$A$967,$A12) -> 6 | F12: =COUNTIFS(calc_lines!$A$2:$A$967,$A12,calc_lines!$W$2:$W$967,"阻断") -> 0 | G12: =IF($F12>0,"",ROUND(SUMIF(calc_lines!$A$2:$A$967,$A12,calc_lines!$R$2:$R$967),2)) -> 221.72 | H12: =IF($F12>0,"",ROUND(SUMIFS(fact_payments!$D$2:$D$101,fact_payments!$B$2:$B$101,$A12,fact_payments!$C$2:$C$101,"<="&checklist!$B$4),2)) -> 221.72 | I12: =IF($F12>0,"",$G12-$H12) -> 0 | J12: =IF($F12>0,"暂缓",IF($I12=0,"已结清","未结清")) -> 已结清
A13: SIM-20260903-C001 | B13: =INDEX(calc_lines!$C$2:$C$967,MATCH($A13,calc_lines!$A$2:$A$967,0)) -> C001 | C13: =INDEX(calc_lines!$O$2:$O$967,MATCH($A13,calc_lines!$A$2:$A$967,0)) -> 模拟_榕树下粉面店 | D13: =INDEX(calc_lines!$D$2:$D$967,MATCH($A13,calc_lines!$A$2:$A$967,0)) -> 46268 | E13: =COUNTIF(calc_lines!$A$2:$A$967,$A13) -> 5 | F13: =COUNTIFS(calc_lines!$A$2:$A$967,$A13,calc_lines!$W$2:$W$967,"阻断") -> 0 | G13: =IF($F13>0,"",ROUND(SUMIF(calc_lines!$A$2:$A$967,$A13,calc_lines!$R$2:$R$967),2)) -> 77.64 | H13: =IF($F13>0,"",ROUND(SUMIFS(fact_payments!$D$2:$D$101,fact_payments!$B$2:$B$101,$A13,fact_payments!$C$2:$C$101,"<="&checklist!$B$4),2)) -> 77.64 | I13: =IF($F13>0,"",$G13-$H13) -> 0 | J13: =IF($F13>0,"暂缓",IF($I13=0,"已结清","未结清")) -> 已结清
... A144: SIM-20260930-C006 | B144: =INDEX(calc_lines!$C$2:$C$967,MATCH($A144,calc_lines!$A$2:$A$967,0)) -> C006 | C144: =INDEX(calc_lines!$O$2:$O$967,MATCH($A144,calc_lines!$A$2:$A$967,0)) -> 模拟_溪桥医院食堂 | D144: =INDEX(calc_lines!$D$2:$D$967,MATCH($A144,calc_lines!$A$2:$A$967,0)) -> 46295 | E144: =COUNTIF(calc_lines!$A$2:$A$967,$A144) -> 6 | F144: =COUNTIFS(calc_lines!$A$2:$A$967,$A144,calc_lines!$W$2:$W$967,"阻断") -> 0 | G144: =IF($F144>0,"",ROUND(SUMIF(calc_lines!$A$2:$A$967,$A144,calc_lines!$R$2:$R$967),2)) -> 228.52 | H144: =IF($F144>0,"",ROUND(SUMIFS(fact_payments!$D$2:$D$101,fact_payments!$B$2:$B$101,$A144,fact_payments!$C$2:$C$101,"<="&checklist!$B$4),2)) -> 0 | I144: =IF($F144>0,"",$G144-$H144) -> 228.52 | J144: =IF($F144>0,"暂缓",IF($I144=0,"已结清","未结清")) -> 未结清

Sheet calc_lines
A1: order_id | B1: line_no | C1: customer_id | D1: order_date | E1: product_id | F1: unit | G1: ordered_qty | H1: delivered_qty | I1: returned_qty | J1: unit_price | K1: delivery_note | L1: is_simulated | M1: product_name | N1: specification | O1: customer_name | P1: gross_amount | Q1: return_amount | R1: net_amount | S1: quantity_exception | T1: unit_exception | U1: price_exception | V1: duplicate_key | W1: data_quality_status
A2: =raw_order_lines!A2 -> SIM-20260901-C001 | B2: =raw_order_lines!B2 -> 1 | C2: =raw_order_lines!C2 -> C001 | D2: =raw_order_lines!D2 -> 46266 | E2: =raw_order_lines!E2 -> P012 | F2: =raw_order_lines!F2 -> 公斤 | G2: =raw_order_lines!G2 -> 4.1 | H2: =raw_order_lines!H2 -> 4.1 | ... L2: =raw_order_lines!L2 -> true | M2: =INDEX(dim_products!$B$2:$B$21,MATCH($E2,dim_products!$A$2:$A$21,0)) -> 小白菜 | N2: =INDEX(dim_products!$C$2:$C$21,MATCH($E2,dim_products!$A$2:$A$21,0)) -> 散装鲜菜 | O2: =INDEX(dim_customers!$B$2:$B$7,MATCH($C2,dim_customers!$A$2:$A$7,0)) -> 模拟_榕树下粉面店 | P2: =INT((ROUND(raw_order_lines!H2*10,0)*ROUND(raw_order_lines!J2*100,0)+5)/10)/100 -> 18.86 | Q2: =INT((ROUND(raw_order_lines!I2*10,0)*ROUND(raw_order_lines!J2*100,0)+5)/10)/100 -> 0 | R2: =$P2-$Q2 -> 18.86 | S2: =IF(OR(ROUND(raw_order_lines!I2*10,0)>ROUND(raw_order_lines!H2*10,0),ROUND(raw_order_lines!H2*10,0)>ROUND(raw_order_lines!G2*10,0),ROUND(raw_order_lines!G2*10,0)<=0),"数量关系异常","") | T2: =IF($F2<>INDEX(dim_products!$D$2:$D$21,MATCH($E2,dim_products!$A$2:$A$21,0)),"单位不一致","") | U2: =IF(OR(ROUND(raw_order_lines!J2*100,0)<ROUND(INDEX(dim_products!$F$2:$F$21,MATCH($E2,dim_products!$A$2:$A$21,0))*100,0),ROUND(raw_order_lines!J2*100,0)>ROUND(INDEX(dim_products!$G$2:$G$21,MATCH($E2,dim_products!$A$2:$A$21,0))*100,0)),"单价越界","") | V2: =IF(COUNTIFS($A$2:$A$967,$A2,$B$2:$B$967,$B2)>1,"主键重复","") | W2: =IF(COUNTIF($S2:$T2,"?*")+COUNTIF($V2:$V2,"?*")>0,"阻断",IF(COUNTIF($U2:$U2,"?*")>0,"提示","通过")) -> 通过
A3: =raw_order_lines!A3 -> SIM-20260901-C001 | B3: =raw_order_lines!B3 -> 2 | C3: =raw_order_lines!C3 -> C001 | D3: =raw_order_lines!D3 -> 46266 | E3: =raw_order_lines!E3 -> P005 | F3: =raw_order_lines!F3 -> 公斤 | G3: =raw_order_lines!G3 -> 3.3 | H3: =raw_order_lines!H3 -> 3.3 | ... L3: =raw_order_lines!L3 -> true | M3: =INDEX(dim_products!$B$2:$B$21,MATCH($E3,dim_products!$A$2:$A$21,0)) -> 南瓜 | N3: =INDEX(dim_products!$C$2:$C$21,MATCH($E3,dim_products!$A$2:$A$21,0)) -> 散装鲜菜 | O3: =INDEX(dim_customers!$B$2:$B$7,MATCH($C3,dim_customers!$A$2:$A$7,0)) -> 模拟_榕树下粉面店 | P3: =INT((ROUND(raw_order_lines!H3*10,0)*ROUND(raw_order_lines!J3*100,0)+5)/10)/100 -> 8.91 | Q3: =INT((ROUND(raw_order_lines!I3*10,0)*ROUND(raw_order_lines!J3*100,0)+5)/10)/100 -> 0 | R3: =$P3-$Q3 -> 8.91 | S3: =IF(OR(ROUND(raw_order_lines!I3*10,0)>ROUND(raw_order_lines!H3*10,0),ROUND(raw_order_lines!H3*10,0)>ROUND(raw_order_lines!G3*10,0),ROUND(raw_order_lines!G3*10,0)<=0),"数量关系异常","") | T3: =IF($F3<>INDEX(dim_products!$D$2:$D$21,MATCH($E3,dim_products!$A$2:$A$21,0)),"单位不一致","") | U3: =IF(OR(ROUND(raw_order_lines!J3*100,0)<ROUND(INDEX(dim_products!$F$2:$F$21,MATCH($E3,dim_products!$A$2:$A$21,0))*100,0),ROUND(raw_order_lines!J3*100,0)>ROUND(INDEX(dim_products!$G$2:$G$21,MATCH($E3,dim_products!$A$2:$A$21,0))*100,0)),"单价越界","") | V3: =IF(COUNTIFS($A$2:$A$967,$A3,$B$2:$B$967,$B3)>1,"主键重复","") | W3: =IF(COUNTIF($S3:$T3,"?*")+COUNTIF($V3:$V3,"?*")>0,"阻断",IF(COUNTIF($U3:$U3,"?*")>0,"提示","通过")) -> 通过
A4: =raw_order_lines!A4 -> SIM-20260901-C001 | B4: =raw_order_lines!B4 -> 3 | C4: =raw_order_lines!C4 -> C001 | D4: =raw_order_lines!D4 -> 46266 | E4: =raw_order_lines!E4 -> P002 | F4: =raw_order_lines!F4 -> 公斤 | G4: =raw_order_lines!G4 -> 2.6 | H4: =raw_order_lines!H4 -> 2.6 | ... L4: =raw_order_lines!L4 -> true | M4: =INDEX(dim_products!$B$2:$B$21,MATCH($E4,dim_products!$A$2:$A$21,0)) -> 白萝卜 | N4: =INDEX(dim_products!$C$2:$C$21,MATCH($E4,dim_products!$A$2:$A$21,0)) -> 散装鲜菜 | O4: =INDEX(dim_customers!$B$2:$B$7,MATCH($C4,dim_customers!$A$2:$A$7,0)) -> 模拟_榕树下粉面店 | P4: =INT((ROUND(raw_order_lines!H4*10,0)*ROUND(raw_order_lines!J4*100,0)+5)/10)/100 -> 5.98 | Q4: =INT((ROUND(raw_order_lines!I4*10,0)*ROUND(raw_order_lines!J4*100,0)+5)/10)/100 -> 0 | R4: =$P4-$Q4 -> 5.98 | S4: =IF(OR(ROUND(raw_order_lines!I4*10,0)>ROUND(raw_order_lines!H4*10,0),ROUND(raw_order_lines!H4*10,0)>ROUND(raw_order_lines!G4*10,0),ROUND(raw_order_lines!G4*10,0)<=0),"数量关系异常","") | T4: =IF($F4<>INDEX(dim_products!$D$2:$D$21,MATCH($E4,dim_products!$A$2:$A$21,0)),"单位不一致","") | U4: =IF(OR(ROUND(raw_order_lines!J4*100,0)<ROUND(INDEX(dim_products!$F$2:$F$21,MATCH($E4,dim_products!$A$2:$A$21,0))*100,0),ROUND(raw_order_lines!J4*100,0)>ROUND(INDEX(dim_products!$G$2:$G$21,MATCH($E4,dim_products!$A$2:$A$21,0))*100,0)),"单价越界","") | V4: =IF(COUNTIFS($A$2:$A$967,$A4,$B$2:$B$967,$B4)>1,"主键重复","") | W4: =IF(COUNTIF($S4:$T4,"?*")+COUNTIF($V4:$V4,"?*")>0,"阻断",IF(COUNTIF($U4:$U4,"?*")>0,"提示","通过")) -> 通过
A5: =raw_order_lines!A5 -> SIM-20260901-C001 | B5: =raw_order_lines!B5 -> 4 | C5: =raw_order_lines!C5 -> C001 | D5: =raw_order_lines!D5 -> 46266 | E5: =raw_order_lines!E5 -> P004 | F5: =raw_order_lines!F5 -> 公斤 | G5: =raw_order_lines!G5 -> 3 | H5: =raw_order_lines!H5 -> 3 | ... L5: =raw_order_lines!L5 -> true | M5: =INDEX(dim_products!$B$2:$B$21,MATCH($E5,dim_products!$A$2:$A$21,0)) -> 冬瓜 | N5: =INDEX(dim_products!$C$2:$C$21,MATCH($E5,dim_products!$A$2:$A$21,0)) -> 散装鲜菜 | O5: =INDEX(dim_customers!$B$2:$B$7,MATCH($C5,dim_customers!$A$2:$A$7,0)) -> 模拟_榕树下粉面店 | P5: =INT((ROUND(raw_order_lines!H5*10,0)*ROUND(raw_order_lines!J5*100,0)+5)/10)/100 -> 6.9 | Q5: =INT((ROUND(raw_order_lines!I5*10,0)*ROUND(raw_order_lines!J5*100,0)+5)/10)/100 -> 0 | R5: =$P5-$Q5 -> 6.9 | S5: =IF(OR(ROUND(raw_order_lines!I5*10,0)>ROUND(raw_order_lines!H5*10,0),ROUND(raw_order_lines!H5*10,0)>ROUND(raw_order_lines!G5*10,0),ROUND(raw_order_lines!G5*10,0)<=0),"数量关系异常","") | T5: =IF($F5<>INDEX(dim_products!$D$2:$D$21,MATCH($E5,dim_products!$A$2:$A$21,0)),"单位不一致","") | U5: =IF(OR(ROUND(raw_order_lines!J5*100,0)<ROUND(INDEX(dim_products!$F$2:$F$21,MATCH($E5,dim_products!$A$2:$A$21,0))*100,0),ROUND(raw_order_lines!J5*100,0)>ROUND(INDEX(dim_products!$G$2:$G$21,MATCH($E5,dim_products!$A$2:$A$21,0))*100,0)),"单价越界","") | V5: =IF(COUNTIFS($A$2:$A$967,$A5,$B$2:$B$967,$B5)>1,"主键重复","") | W5: =IF(COUNTIF($S5:$T5,"?*")+COUNTIF($V5:$V5,"?*")>0,"阻断",IF(COUNTIF($U5:$U5,"?*")>0,"提示","通过")) -> 通过
A6: =raw_order_lines!A6 -> SIM-20260901-C001 | B6: =raw_order_lines!B6 -> 5 | C6: =raw_order_lines!C6 -> C001 | D6: =raw_order_lines!D6 -> 46266 | E6: =raw_order_lines!E6 -> P016 | F6: =raw_order_lines!F6 -> 公斤 | G6: =raw_order_lines!G6 -> 3 | H6: =raw_order_lines!H6 -> 3 | ... L6: =raw_order_lines!L6 -> true | M6: =INDEX(dim_products!$B$2:$B$21,MATCH($E6,dim_products!$A$2:$A$21,0)) -> 鸡蛋 | N6: =INDEX(dim_products!$C$2:$C$21,MATCH($E6,dim_products!$A$2:$A$21,0)) -> 普通鲜鸡蛋按净重 | O6: =INDEX(dim_customers!$B$2:$B$7,MATCH($C6,dim_customers!$A$2:$A$7,0)) -> 模拟_榕树下粉面店 | P6: =INT((ROUND(raw_order_lines!H6*10,0)*ROUND(raw_order_lines!J6*100,0)+5)/10)/100 -> 30.3 | Q6: =INT((ROUND(raw_order_lines!I6*10,0)*ROUND(raw_order_lines!J6*100,0)+5)/10)/100 -> 0 | R6: =$P6-$Q6 -> 30.3 | S6: =IF(OR(ROUND(raw_order_lines!I6*10,0)>ROUND(raw_order_lines!H6*10,0),ROUND(raw_order_lines!H6*10,0)>ROUND(raw_order_lines!G6*10,0),ROUND(raw_order_lines!G6*10,0)<=0),"数量关系异常","") | T6: =IF($F6<>INDEX(dim_products!$D$2:$D$21,MATCH($E6,dim_products!$A$2:$A$21,0)),"单位不一致","") | U6: =IF(OR(ROUND(raw_order_lines!J6*100,0)<ROUND(INDEX(dim_products!$F$2:$F$21,MATCH($E6,dim_products!$A$2:$A$21,0))*100,0),ROUND(raw_order_lines!J6*100,0)>ROUND(INDEX(dim_products!$G$2:$G$21,MATCH($E6,dim_products!$A$2:$A$21,0))*100,0)),"单价越界","") | V6: =IF(COUNTIFS($A$2:$A$967,$A6,$B$2:$B$967,$B6)>1,"主键重复","") | W6: =IF(COUNTIF($S6:$T6,"?*")+COUNTIF($V6:$V6,"?*")>0,"阻断",IF(COUNTIF($U6:$U6,"?*")>0,"提示","通过")) -> 通过
A7: =raw_order_lines!A7 -> SIM-20260901-C001 | B7: =raw_order_lines!B7 -> 6 | C7: =raw_order_lines!C7 -> C001 | D7: =raw_order_lines!D7 -> 46266 | E7: =raw_order_lines!E7 -> P015 | F7: =raw_order_lines!F7 -> 公斤 | G7: =raw_order_lines!G7 -> 0.5 | H7: =raw_order_lines!H7 -> 0.5 | ... L7: =raw_order_lines!L7 -> true | M7: =INDEX(dim_products!$B$2:$B$21,MATCH($E7,dim_products!$A$2:$A$21,0)) -> 小葱 | N7: =INDEX(dim_products!$C$2:$C$21,MATCH($E7,dim_products!$A$2:$A$21,0)) -> 散装鲜菜 | O7: =INDEX(dim_customers!$B$2:$B$7,MATCH($C7,dim_customers!$A$2:$A$7,0)) -> 模拟_榕树下粉面店 | P7: =INT((ROUND(raw_order_lines!H7*10,0)*ROUND(raw_order_lines!J7*100,0)+5)/10)/100 -> 3.65 | Q7: =INT((ROUND(raw_order_lines!I7*10,0)*ROUND(raw_order_lines!J7*100,0)+5)/10)/100 -> 0 | R7: =$P7-$Q7 -> 3.65 | S7: =IF(OR(ROUND(raw_order_lines!I7*10,0)>ROUND(raw_order_lines!H7*10,0),ROUND(raw_order_lines!H7*10,0)>ROUND(raw_order_lines!G7*10,0),ROUND(raw_order_lines!G7*10,0)<=0),"数量关系异常","") | T7: =IF($F7<>INDEX(dim_products!$D$2:$D$21,MATCH($E7,dim_products!$A$2:$A$21,0)),"单位不一致","") | U7: =IF(OR(ROUND(raw_order_lines!J7*100,0)<ROUND(INDEX(dim_products!$F$2:$F$21,MATCH($E7,dim_products!$A$2:$A$21,0))*100,0),ROUND(raw_order_lines!J7*100,0)>ROUND(INDEX(dim_products!$G$2:$G$21,MATCH($E7,dim_products!$A$2:$A$21,0))*100,0)),"单价越界","") | V7: =IF(COUNTIFS($A$2:$A$967,$A7,$B$2:$B$967,$B7)>1,"主键重复","") | W7: =IF(COUNTIF($S7:$T7,"?*")+COUNTIF($V7:$V7,"?*")>0,"阻断",IF(COUNTIF($U7:$U7,"?*")>0,"提示","通过")) -> 通过
A8: =raw_order_lines!A8 -> SIM-20260901-C001 | B8: =raw_order_lines!B8 -> 7 | C8: =raw_order_lines!C8 -> C001 | D8: =raw_order_lines!D8 -> 46266 | E8: =raw_order_lines!E8 -> P019 | F8: =raw_order_lines!F8 -> 桶 | G8: =raw_order_lines!G8 -> 1 | H8: =raw_order_lines!H8 -> 1 | ... L8: =raw_order_lines!L8 -> true | M8: =INDEX(dim_products!$B$2:$B$21,MATCH($E8,dim_products!$A$2:$A$21,0)) -> 菜籽油 | N8: =INDEX(dim_products!$C$2:$C$21,MATCH($E8,dim_products!$A$2:$A$21,0)) -> 5升/桶普通菜籽油 | O8: =INDEX(dim_customers!$B$2:$B$7,MATCH($C8,dim_customers!$A$2:$A$7,0)) -> 模拟_榕树下粉面店 | P8: =INT((ROUND(raw_order_lines!H8*10,0)*ROUND(raw_order_lines!J8*100,0)+5)/10)/100 -> 71 | Q8: =INT((ROUND(raw_order_lines!I8*10,0)*ROUND(raw_order_lines!J8*100,0)+5)/10)/100 -> 0 | R8: =$P8-$Q8 -> 71 | S8: =IF(OR(ROUND(raw_order_lines!I8*10,0)>ROUND(raw_order_lines!H8*10,0),ROUND(raw_order_lines!H8*10,0)>ROUND(raw_order_lines!G8*10,0),ROUND(raw_order_lines!G8*10,0)<=0),"数量关系异常","") | T8: =IF($F8<>INDEX(dim_products!$D$2:$D$21,MATCH($E8,dim_products!$A$2:$A$21,0)),"单位不一致","") | U8: =IF(OR(ROUND(raw_order_lines!J8*100,0)<ROUND(INDEX(dim_products!$F$2:$F$21,MATCH($E8,dim_products!$A$2:$A$21,0))*100,0),ROUND(raw_order_lines!J8*100,0)>ROUND(INDEX(dim_products!$G$2:$G$21,MATCH($E8,dim_products!$A$2:$A$21,0))*100,0)),"单价越界","") | V8: =IF(COUNTIFS($A$2:$A$967,$A8,$B$2:$B$967,$B8)>1,"主键重复","") | W8: =IF(COUNTIF($S8:$T8,"?*")+COUNTIF($V8:$V8,"?*")>0,"阻断",IF(COUNTIF($U8:$U8,"?*")>0,"提示","通过")) -> 通过
A9: =raw_order_lines!A9 -> SIM-20260901-C001 | B9: =raw_order_lines!B9 -> 8 | C9: =raw_order_lines!C9 -> C001 | D9: =raw_order_lines!D9 -> 46266 | E9: =raw_order_lines!E9 -> P018 | F9: =raw_order_lines!F9 -> 袋 | G9: =raw_order_lines!G9 -> 1 | H9: =raw_order_lines!H9 -> 1 | ... L9: =raw_order_lines!L9 -> true | M9: =INDEX(dim_products!$B$2:$B$21,MATCH($E9,dim_products!$A$2:$A$21,0)) -> 小麦粉 | N9: =INDEX(dim_products!$C$2:$C$21,MATCH($E9,dim_products!$A$2:$A$21,0)) -> 25公斤/袋普通小麦粉 | O9: =INDEX(dim_customers!$B$2:$B$7,MATCH($C9,dim_customers!$A$2:$A$7,0)) -> 模拟_榕树下粉面店 | P9: =INT((ROUND(raw_order_lines!H9*10,0)*ROUND(raw_order_lines!J9*100,0)+5)/10)/100 -> 111 | Q9: =INT((ROUND(raw_order_lines!I9*10,0)*ROUND(raw_order_lines!J9*100,0)+5)/10)/100 -> 0 | R9: =$P9-$Q9 -> 111 | S9: =IF(OR(ROUND(raw_order_lines!I9*10,0)>ROUND(raw_order_lines!H9*10,0),ROUND(raw_order_lines!H9*10,0)>ROUND(raw_order_lines!G9*10,0),ROUND(raw_order_lines!G9*10,0)<=0),"数量关系异常","") | T9: =IF($F9<>INDEX(dim_products!$D$2:$D$21,MATCH($E9,dim_products!$A$2:$A$21,0)),"单位不一致","") | U9: =IF(OR(ROUND(raw_order_lines!J9*100,0)<ROUND(INDEX(dim_products!$F$2:$F$21,MATCH($E9,dim_products!$A$2:$A$21,0))*100,0),ROUND(raw_order_lines!J9*100,0)>ROUND(INDEX(dim_products!$G$2:$G$21,MATCH($E9,dim_products!$A$2:$A$21,0))*100,0)),"单价越界","") | V9: =IF(COUNTIFS($A$2:$A$967,$A9,$B$2:$B$967,$B9)>1,"主键重复","") | W9: =IF(COUNTIF($S9:$T9,"?*")+COUNTIF($V9:$V9,"?*")>0,"阻断",IF(COUNTIF($U9:$U9,"?*")>0,"提示","通过")) -> 通过
A10: =raw_order_lines!A10 -> SIM-20260901-C002 | B10: =raw_order_lines!B10 -> 1 | C10: =raw_order_lines!C10 -> C002 | D10: =raw_order_lines!D10 -> 46266 | E10: =raw_order_lines!E10 -> P011 | F10: =raw_order_lines!F10 -> 公斤 | G10: =raw_order_lines!G10 -> 4.5 | H10: =raw_order_lines!H10 -> 4.5 | ... L10: =raw_order_lines!L10 -> true | M10: =INDEX(dim_products!$B$2:$B$21,MATCH($E10,dim_products!$A$2:$A$21,0)) -> 红薯叶 | N10: =INDEX(dim_products!$C$2:$C$21,MATCH($E10,dim_products!$A$2:$A$21,0)) -> 散装鲜菜 | O10: =INDEX(dim_customers!$B$2:$B$7,MATCH($C10,dim_customers!$A$2:$A$7,0)) -> 模拟_桥头家常菜馆 | P10: =INT((ROUND(raw_order_lines!H10*10,0)*ROUND(raw_order_lines!J10*100,0)+5)/10)/100 -> 19.8 | Q10: =INT((ROUND(raw_order_lines!I10*10,0)*ROUND(raw_order_lines!J10*100,0)+5)/10)/100 -> 0 | R10: =$P10-$Q10 -> 19.8 | S10: =IF(OR(ROUND(raw_order_lines!I10*10,0)>ROUND(raw_order_lines!H10*10,0),ROUND(raw_order_lines!H10*10,0)>ROUND(raw_order_lines!G10*10,0),ROUND(raw_order_lines!G10*10,0)<=0),"数量关系异常","") | T10: =IF($F10<>INDEX(dim_products!$D$2:$D$21,MATCH($E10,dim_products!$A$2:$A$21,0)),"单位不一致","") | U10: =IF(OR(ROUND(raw_order_lines!J10*100,0)<ROUND(INDEX(dim_products!$F$2:$F$21,MATCH($E10,dim_products!$A$2:$A$21,0))*100,0),ROUND(raw_order_lines!J10*100,0)>ROUND(INDEX(dim_products!$G$2:$G$21,MATCH($E10,dim_products!$A$2:$A$21,0))*100,0)),"单价越界","") | V10: =IF(COUNTIFS($A$2:$A$967,$A10,$B$2:$B$967,$B10)>1,"主键重复","") | W10: =IF(COUNTIF($S10:$T10,"?*")+COUNTIF($V10:$V10,"?*")>0,"阻断",IF(COUNTIF($U10:$U10,"?*")>0,"提示","通过")) -> 通过
A11: =raw_order_lines!A11 -> SIM-20260901-C002 | B11: =raw_order_lines!B11 -> 2 | C11: =raw_order_lines!C11 -> C002 | D11: =raw_order_lines!D11 -> 46266 | E11: =raw_order_lines!E11 -> P001 | F11: =raw_order_lines!F11 -> 公斤 | G11: =raw_order_lines!G11 -> 4.5 | H11: =raw_order_lines!H11 -> 4.5 | ... L11: =raw_order_lines!L11 -> true | M11: =INDEX(dim_products!$B$2:$B$21,MATCH($E11,dim_products!$A$2:$A$21,0)) -> 土豆 | N11: =INDEX(dim_products!$C$2:$C$21,MATCH($E11,dim_products!$A$2:$A$21,0)) -> 散装鲜菜 | O11: =INDEX(dim_customers!$B$2:$B$7,MATCH($C11,dim_customers!$A$2:$A$7,0)) -> 模拟_桥头家常菜馆 | P11: =INT((ROUND(raw_order_lines!H11*10,0)*ROUND(raw_order_lines!J11*100,0)+5)/10)/100 -> 14.85 | Q11: =INT((ROUND(raw_order_lines!I11*10,0)*ROUND(raw_order_lines!J11*100,0)+5)/10)/100 -> 0 | R11: =$P11-$Q11 -> 14.85 | S11: =IF(OR(ROUND(raw_order_lines!I11*10,0)>ROUND(raw_order_lines!H11*10,0),ROUND(raw_order_lines!H11*10,0)>ROUND(raw_order_lines!G11*10,0),ROUND(raw_order_lines!G11*10,0)<=0),"数量关系异常","") | T11: =IF($F11<>INDEX(dim_products!$D$2:$D$21,MATCH($E11,dim_products!$A$2:$A$21,0)),"单位不一致","") | U11: =IF(OR(ROUND(raw_order_lines!J11*100,0)<ROUND(INDEX(dim_products!$F$2:$F$21,MATCH($E11,dim_products!$A$2:$A$21,0))*100,0),ROUND(raw_order_lines!J11*100,0)>ROUND(INDEX(dim_products!$G$2:$G$21,MATCH($E11,dim_products!$A$2:$A$21,0))*100,0)),"单价越界","") | V11: =IF(COUNTIFS($A$2:$A$967,$A11,$B$2:$B$967,$B11)>1,"主键重复","") | W11: =IF(COUNTIF($S11:$T11,"?*")+COUNTIF($V11:$V11,"?*")>0,"阻断",IF(COUNTIF($U11:$U11,"?*")>0,"提示","通过")) -> 通过
A12: =raw_order_lines!A12 -> SIM-20260901-C002 | B12: =raw_order_lines!B12 -> 3 | C12: =raw_order_lines!C12 -> C002 | D12: =raw_order_lines!D12 -> 46266 | E12: =raw_order_lines!E12 -> P006 | F12: =raw_order_lines!F12 -> 公斤 | G12: =raw_order_lines!G12 -> 9 | H12: =raw_order_lines!H12 -> 9 | ... L12: =raw_order_lines!L12 -> true | M12: =INDEX(dim_products!$B$2:$B$21,MATCH($E12,dim_products!$A$2:$A$21,0)) -> 茄子 | N12: =INDEX(dim_products!$C$2:$C$21,MATCH($E12,dim_products!$A$2:$A$21,0)) -> 散装鲜菜 | O12: =INDEX(dim_customers!$B$2:$B$7,MATCH($C12,dim_customers!$A$2:$A$7,0)) -> 模拟_桥头家常菜馆 | P12: =INT((ROUND(raw_order_lines!H12*10,0)*ROUND(raw_order_lines!J12*100,0)+5)/10)/100 -> 41.4 | Q12: =INT((ROUND(raw_order_lines!I12*10,0)*ROUND(raw_order_lines!J12*100,0)+5)/10)/100 -> 0 | R12: =$P12-$Q12 -> 41.4 | S12: =IF(OR(ROUND(raw_order_lines!I12*10,0)>ROUND(raw_order_lines!H12*10,0),ROUND(raw_order_lines!H12*10,0)>ROUND(raw_order_lines!G12*10,0),ROUND(raw_order_lines!G12*10,0)<=0),"数量关系异常","") | T12: =IF($F12<>INDEX(dim_products!$D$2:$D$21,MATCH($E12,dim_products!$A$2:$A$21,0)),"单位不一致","") | U12: =IF(OR(ROUND(raw_order_lines!J12*100,0)<ROUND(INDEX(dim_products!$F$2:$F$21,MATCH($E12,dim_products!$A$2:$A$21,0))*100,0),ROUND(raw_order_lines!J12*100,0)>ROUND(INDEX(dim_products!$G$2:$G$21,MATCH($E12,dim_products!$A$2:$A$21,0))*100,0)),"单价越界","") | V12: =IF(COUNTIFS($A$2:$A$967,$A12,$B$2:$B$967,$B12)>1,"主键重复","") | W12: =IF(COUNTIF($S12:$T12,"?*")+COUNTIF($V12:$V12,"?*")>0,"阻断",IF(COUNTIF($U12:$U12,"?*")>0,"提示","通过")) -> 通过
A13: =raw_order_lines!A13 -> SIM-20260901-C002 | B13: =raw_order_lines!B13 -> 4 | C13: =raw_order_lines!C13 -> C002 | D13: =raw_order_lines!D13 -> 46266 | E13: =raw_order_lines!E13 -> P013 | F13: =raw_order_lines!F13 -> 公斤 | G13: =raw_order_lines!G13 -> 4.5 | H13: =raw_order_lines!H13 -> 4.5 | ... L13: =raw_order_lines!L13 -> true | M13: =INDEX(dim_products!$B$2:$B$21,MATCH($E13,dim_products!$A$2:$A$21,0)) -> 豇豆 | N13: =INDEX(dim_products!$C$2:$C$21,MATCH($E13,dim_products!$A$2:$A$21,0)) -> 散装鲜菜 | O13: =INDEX(dim_customers!$B$2:$B$7,MATCH($C13,dim_customers!$A$2:$A$7,0)) -> 模拟_桥头家常菜馆 | P13: =INT((ROUND(raw_order_lines!H13*10,0)*ROUND(raw_order_lines!J13*100,0)+5)/10)/100 -> 28.35 | Q13: =INT((ROUND(raw_order_lines!I13*10,0)*ROUND(raw_order_lines!J13*100,0)+5)/10)/100 -> 0 | R13: =$P13-$Q13 -> 28.35 | S13: =IF(OR(ROUND(raw_order_lines!I13*10,0)>ROUND(raw_order_lines!H13*10,0),ROUND(raw_order_lines!H13*10,0)>ROUND(raw_order_lines!G13*10,0),ROUND(raw_order_lines!G13*10,0)<=0),"数量关系异常","") | T13: =IF($F13<>INDEX(dim_products!$D$2:$D$21,MATCH($E13,dim_products!$A$2:$A$21,0)),"单位不一致","") | U13: =IF(OR(ROUND(raw_order_lines!J13*100,0)<ROUND(INDEX(dim_products!$F$2:$F$21,MATCH($E13,dim_products!$A$2:$A$21,0))*100,0),ROUND(raw_order_lines!J13*100,0)>ROUND(INDEX(dim_products!$G$2:$G$21,MATCH($E13,dim_products!$A$2:$A$21,0))*100,0)),"单价越界","") | V13: =IF(COUNTIFS($A$2:$A$967,$A13,$B$2:$B$967,$B13)>1,"主键重复","") | W13: =IF(COUNTIF($S13:$T13,"?*")+COUNTIF($V13:$V13,"?*")>0,"阻断",IF(COUNTIF($U13:$U13,"?*")>0,"提示","通过")) -> 通过
... A967: =raw_order_lines!A967 -> SIM-20260930-C006 | B967: =raw_order_lines!B967 -> 6 | C967: =raw_order_lines!C967 -> C006 | D967: =raw_order_lines!D967 -> 46295 | E967: =raw_order_lines!E967 -> P001 | F967: =raw_order_lines!F967 -> 公斤 | G967: =raw_order_lines!G967 -> 5.5 | H967: =raw_order_lines!H967 -> 5.5 | ... L967: =raw_order_lines!L967 -> true | M967: =INDEX(dim_products!$B$2:$B$21,MATCH($E967,dim_products!$A$2:$A$21,0)) -> 土豆 | N967: =INDEX(dim_products!$C$2:$C$21,MATCH($E967,dim_products!$A$2:$A$21,0)) -> 散装鲜菜 | O967: =INDEX(dim_customers!$B$2:$B$7,MATCH($C967,dim_customers!$A$2:$A$7,0)) -> 模拟_溪桥医院食堂 | P967: =INT((ROUND(raw_order_lines!H967*10,0)*ROUND(raw_order_lines!J967*100,0)+5)/10)/100 -> 17.05 | Q967: =INT((ROUND(raw_order_lines!I967*10,0)*ROUND(raw_order_lines!J967*100,0)+5)/10)/100 -> 0 | R967: =$P967-$Q967 -> 17.05 | S967: =IF(OR(ROUND(raw_order_lines!I967*10,0)>ROUND(raw_order_lines!H967*10,0),ROUND(raw_order_lines!H967*10,0)>ROUND(raw_order_lines!G967*10,0),ROUND(raw_order_lines!G967*10,0)<=0),"数量关系异常","") | T967: =IF($F967<>INDEX(dim_products!$D$2:$D$21,MATCH($E967,dim_products!$A$2:$A$21,0)),"单位不一致","") | U967: =IF(OR(ROUND(raw_order_lines!J967*100,0)<ROUND(INDEX(dim_products!$F$2:$F$21,MATCH($E967,dim_products!$A$2:$A$21,0))*100,0),ROUND(raw_order_lines!J967*100,0)>ROUND(INDEX(dim_products!$G$2:$G$21,MATCH($E967,dim_products!$A$2:$A$21,0))*100,0)),"单价越界","") | V967: =IF(COUNTIFS($A$2:$A$967,$A967,$B$2:$B$967,$B967)>1,"主键重复","") | W967: =IF(COUNTIF($S967:$T967,"?*")+COUNTIF($V967:$V967,"?*")>0,"阻断",IF(COUNTIF($U967:$U967,"?*")>0,"提示","通过")) -> 通过

Sheet pivot_report
A1: 交叉汇总视图
A2: 公式汇总与 calc_customers、calc_lines 对拍；在 Excel 中可从 calc_lines 插入原生透视表
A4: 客户 | B4: 净应收 | C4: 已收 | D4: 未结清 | F4: 日期 | G4: 下单数量 | H4: 交付数量 | I4: 少送数量
A5: =calc_customers!B2 -> 模拟_榕树下粉面店 | B5: =calc_customers!D2 -> 2765.55 | C5: =calc_customers!E2 -> 2765.55 | D5: =calc_customers!F2 -> 0 | F5: 46266 | G5: =SUMIFS(calc_lines!$G$2:$G$967,calc_lines!$D$2:$D$967,$F5) -> 311.6 | H5: =SUMIFS(calc_lines!$H$2:$H$967,calc_lines!$D$2:$D$967,$F5) -> 310.6 | I5: =G5-H5 -> 1
A6: =calc_customers!B3 -> 模拟_桥头家常菜馆 | B6: =calc_customers!D3 -> 6594.59 | C6: =calc_customers!E3 -> 6594.59 | D6: =calc_customers!F3 -> 0 | F6: 46267 | G6: =SUMIFS(calc_lines!$G$2:$G$967,calc_lines!$D$2:$D$967,$F6) -> 190.5 | H6: =SUMIFS(calc_lines!$H$2:$H$967,calc_lines!$D$2:$D$967,$F6) -> 190.5 | I6: =G6-H6 -> 0
A7: =calc_customers!B4 -> 模拟_兴街快餐店 | B7: =calc_customers!D4 -> 9536.72 | C7: =calc_customers!E4 -> 3000 | D7: =calc_customers!F4 -> 6536.72 | F7: 46268 | G7: =SUMIFS(calc_lines!$G$2:$G$967,calc_lines!$D$2:$D$967,$F7) -> 257.7 | H7: =SUMIFS(calc_lines!$H$2:$H$967,calc_lines!$D$2:$D$967,$F7) -> 256.3 | I7: =G7-H7 -> 1.4
A8: =calc_customers!B5 -> 模拟_田畔饭店 | B8: =calc_customers!D5 -> 3894.01 | C8: =calc_customers!E5 -> 3894.01 | D8: =calc_customers!F5 -> 0 | F8: 46269 | G8: =SUMIFS(calc_lines!$G$2:$G$967,calc_lines!$D$2:$D$967,$F8) -> 204 | H8: =SUMIFS(calc_lines!$H$2:$H$967,calc_lines!$D$2:$D$967,$F8) -> 203.8 | I8: =G8-H8 -> 0.2
A9: =calc_customers!B6 -> 模拟_青禾小学食堂 | B9: =calc_customers!D6 -> 11237.09 | C9: =calc_customers!E6 -> 5000 | D9: =calc_customers!F6 -> 6237.09 | F9: 46270 | G9: =SUMIFS(calc_lines!$G$2:$G$967,calc_lines!$D$2:$D$967,$F9) -> 213.7 | H9: =SUMIFS(calc_lines!$H$2:$H$967,calc_lines!$D$2:$D$967,$F9) -> 212.7 | I9: =G9-H9 -> 1
A10: =calc_customers!B7 -> 模拟_溪桥医院食堂 | B10: =calc_customers!D7 -> 10886.34 | C10: =calc_customers!E7 -> 5000 | D10: =calc_customers!F7 -> 5886.34 | F10: 46271 | G10: =SUMIFS(calc_lines!$G$2:$G$967,calc_lines!$D$2:$D$967,$F10) -> 88.6 | H10: =SUMIFS(calc_lines!$H$2:$H$967,calc_lines!$D$2:$D$967,$F10) -> 88.6 | I10: =G10-H10 -> 0
F11: 46272 | G11: =SUMIFS(calc_lines!$G$2:$G$967,calc_lines!$D$2:$D$967,$F11) -> 196.4 | H11: =SUMIFS(calc_lines!$H$2:$H$967,calc_lines!$D$2:$D$967,$F11) -> 195.9 | I11: =G11-H11 -> 0.5
A12: 商品 | B12: 单位 | C12: 交付数量 | D12: 退货数量 | F12: 46273 | G12: =SUMIFS(calc_lines!$G$2:$G$967,calc_lines!$D$2:$D$967,$F12) -> 247.6 | H12: =SUMIFS(calc_lines!$H$2:$H$967,calc_lines!$D$2:$D$967,$F12) -> 247.1 | I12: =G12-H12 -> 0.5
A13: =dim_products!B2 -> 土豆 | B13: =dim_products!D2 -> 公斤 | C13: =SUMIFS(calc_lines!$H$2:$H$967,calc_lines!$E$2:$E$967,dim_products!$A2) -> 443 | D13: =SUMIFS(calc_lines!$I$2:$I$967,calc_lines!$E$2:$E$967,dim_products!$A2) -> 0 | F13: 46274 | G13: =SUMIFS(calc_lines!$G$2:$G$967,calc_lines!$D$2:$D$967,$F13) -> 205.8 | H13: =SUMIFS(calc_lines!$H$2:$H$967,calc_lines!$D$2:$D$967,$F13) -> 205.6 | I13: =G13-H13 -> 0.2
A14: =dim_products!B3 -> 白萝卜 | B14: =dim_products!D3 -> 公斤 | C14: =SUMIFS(calc_lines!$H$2:$H$967,calc_lines!$E$2:$E$967,dim_products!$A3) -> 384.9 | D14: =SUMIFS(calc_lines!$I$2:$I$967,calc_lines!$E$2:$E$967,dim_products!$A3) -> 0 | F14: 46275 | G14: =SUMIFS(calc_lines!$G$2:$G$967,calc_lines!$D$2:$D$967,$F14) -> 235.7 | H14: =SUMIFS(calc_lines!$H$2:$H$967,calc_lines!$D$2:$D$967,$F14) -> 235 | I14: =G14-H14 -> 0.7
A15: =dim_products!B4 -> 包菜 | B15: =dim_products!D4 -> 公斤 | C15: =SUMIFS(calc_lines!$H$2:$H$967,calc_lines!$E$2:$E$967,dim_products!$A4) -> 440 | D15: =SUMIFS(calc_lines!$I$2:$I$967,calc_lines!$E$2:$E$967,dim_products!$A4) -> 0 | F15: 46276 | G15: =SUMIFS(calc_lines!$G$2:$G$967,calc_lines!$D$2:$D$967,$F15) -> 233.8 | H15: =SUMIFS(calc_lines!$H$2:$H$967,calc_lines!$D$2:$D$967,$F15) -> 233.5 | I15: =G15-H15 -> 0.3
A16: =dim_products!B5 -> 冬瓜 | B16: =dim_products!D5 -> 公斤 | C16: =SUMIFS(calc_lines!$H$2:$H$967,calc_lines!$E$2:$E$967,dim_products!$A5) -> 392.6 | D16: =SUMIFS(calc_lines!$I$2:$I$967,calc_lines!$E$2:$E$967,dim_products!$A5) -> 0 | F16: 46277 | G16: =SUMIFS(calc_lines!$G$2:$G$967,calc_lines!$D$2:$D$967,$F16) -> 200.3 | H16: =SUMIFS(calc_lines!$H$2:$H$967,calc_lines!$D$2:$D$967,$F16) -> 199.8 | I16: =G16-H16 -> 0.5
A17: =dim_products!B6 -> 南瓜 | B17: =dim_products!D6 -> 公斤 | C17: =SUMIFS(calc_lines!$H$2:$H$967,calc_lines!$E$2:$E$967,dim_products!$A6) -> 376 | D17: =SUMIFS(calc_lines!$I$2:$I$967,calc_lines!$E$2:$E$967,dim_products!$A6) -> 0 | F17: 46278 | G17: =SUMIFS(calc_lines!$G$2:$G$967,calc_lines!$D$2:$D$967,$F17) -> 93.1 | H17: =SUMIFS(calc_lines!$H$2:$H$967,calc_lines!$D$2:$D$967,$F17) -> 92 | I17: =G17-H17 -> 1.1
A18: =dim_products!B7 -> 茄子 | B18: =dim_products!D7 -> 公斤 | C18: =SUMIFS(calc_lines!$H$2:$H$967,calc_lines!$E$2:$E$967,dim_products!$A7) -> 447.4 | D18: =SUMIFS(calc_lines!$I$2:$I$967,calc_lines!$E$2:$E$967,dim_products!$A7) -> 0 | F18: 46279 | G18: =SUMIFS(calc_lines!$G$2:$G$967,calc_lines!$D$2:$D$967,$F18) -> 158.4 | H18: =SUMIFS(calc_lines!$H$2:$H$967,calc_lines!$D$2:$D$967,$F18) -> 157.7 | I18: =G18-H18 -> 0.7
A19: =dim_products!B8 -> 青椒 | B19: =dim_products!D8 -> 公斤 | C19: =SUMIFS(calc_lines!$H$2:$H$967,calc_lines!$E$2:$E$967,dim_products!$A8) -> 381 | D19: =SUMIFS(calc_lines!$I$2:$I$967,calc_lines!$E$2:$E$967,dim_products!$A8) -> 0 | F19: 46280 | G19: =SUMIFS(calc_lines!$G$2:$G$967,calc_lines!$D$2:$D$967,$F19) -> 291.5 | H19: =SUMIFS(calc_lines!$H$2:$H$967,calc_lines!$D$2:$D$967,$F19) -> 291.5 | I19: =G19-H19 -> 0
A20: =dim_products!B9 -> 黄瓜 | B20: =dim_products!D9 -> 公斤 | C20: =SUMIFS(calc_lines!$H$2:$H$967,calc_lines!$E$2:$E$967,dim_products!$A9) -> 453.8 | D20: =SUMIFS(calc_lines!$I$2:$I$967,calc_lines!$E$2:$E$967,dim_products!$A9) -> 0 | F20: 46281 | G20: =SUMIFS(calc_lines!$G$2:$G$967,calc_lines!$D$2:$D$967,$F20) -> 195.3 | H20: =SUMIFS(calc_lines!$H$2:$H$967,calc_lines!$D$2:$D$967,$F20) -> 195.3 | I20: =G20-H20 -> 0
A21: =dim_products!B10 -> 西红柿 | B21: =dim_products!D10 -> 公斤 | C21: =SUMIFS(calc_lines!$H$2:$H$967,calc_lines!$E$2:$E$967,dim_products!$A10) -> 421.3 | D21: =SUMIFS(calc_lines!$I$2:$I$967,calc_lines!$E$2:$E$967,dim_products!$A10) -> 0 | F21: 46282 | G21: =SUMIFS(calc_lines!$G$2:$G$967,calc_lines!$D$2:$D$967,$F21) -> 273.6 | H21: =SUMIFS(calc_lines!$H$2:$H$967,calc_lines!$D$2:$D$967,$F21) -> 271.8 | I21: =G21-H21 -> 1.8
A22: =dim_products!B11 -> 空心菜 | B22: =dim_products!D11 -> 公斤 | C22: =SUMIFS(calc_lines!$H$2:$H$967,calc_lines!$E$2:$E$967,dim_products!$A11) -> 274.7 | D22: =SUMIFS(calc_lines!$I$2:$I$967,calc_lines!$E$2:$E$967,dim_products!$A11) -> 1.2 | F22: 46283 | G22: =SUMIFS(calc_lines!$G$2:$G$967,calc_lines!$D$2:$D$967,$F22) -> 216.2 | H22: =SUMIFS(calc_lines!$H$2:$H$967,calc_lines!$D$2:$D$967,$F22) -> 215.4 | I22: =G22-H22 -> 0.8
A23: =dim_products!B12 -> 红薯叶 | B23: =dim_products!D12 -> 公斤 | C23: =SUMIFS(calc_lines!$H$2:$H$967,calc_lines!$E$2:$E$967,dim_products!$A12) -> 343.6 | D23: =SUMIFS(calc_lines!$I$2:$I$967,calc_lines!$E$2:$E$967,dim_products!$A12) -> 3 | F23: 46284 | G23: =SUMIFS(calc_lines!$G$2:$G$967,calc_lines!$D$2:$D$967,$F23) -> 219.5 | H23: =SUMIFS(calc_lines!$H$2:$H$967,calc_lines!$D$2:$D$967,$F23) -> 218.5 | I23: =G23-H23 -> 1
A24: =dim_products!B13 -> 小白菜 | B24: =dim_products!D13 -> 公斤 | C24: =SUMIFS(calc_lines!$H$2:$H$967,calc_lines!$E$2:$E$967,dim_products!$A13) -> 359.6 | D24: =SUMIFS(calc_lines!$I$2:$I$967,calc_lines!$E$2:$E$967,dim_products!$A13) -> 2.9 | F24: 46285 | G24: =SUMIFS(calc_lines!$G$2:$G$967,calc_lines!$D$2:$D$967,$F24) -> 171.4 | H24: =SUMIFS(calc_lines!$H$2:$H$967,calc_lines!$D$2:$D$967,$F24) -> 171.1 | I24: =G24-H24 -> 0.3
... A32: =dim_products!B21 -> 大豆油 | B32: =dim_products!D21 -> 桶 | C32: =SUMIFS(calc_lines!$H$2:$H$967,calc_lines!$E$2:$E$967,dim_products!$A21) -> 34 | D32: =SUMIFS(calc_lines!$I$2:$I$967,calc_lines!$E$2:$E$967,dim_products!$A21) -> 0 | F32: 46293 | G32: =SUMIFS(calc_lines!$G$2:$G$967,calc_lines!$D$2:$D$967,$F32) -> 158.3 | H32: =SUMIFS(calc_lines!$H$2:$H$967,calc_lines!$D$2:$D$967,$F32) -> 157.4 | I32: =G32-H32 -> 0.9
F33: 46294 | G33: =SUMIFS(calc_lines!$G$2:$G$967,calc_lines!$D$2:$D$967,$F33) -> 283.3 | H33: =SUMIFS(calc_lines!$H$2:$H$967,calc_lines!$D$2:$D$967,$F33) -> 282.8 | I33: =G33-H33 -> 0.5
F34: 46295 | G34: =SUMIFS(calc_lines!$G$2:$G$967,calc_lines!$D$2:$D$967,$F34) -> 197.4 | H34: =SUMIFS(calc_lines!$H$2:$H$967,calc_lines!$D$2:$D$967,$F34) -> 196.4 | I34: =G34-H34 -> 1

Sheet exceptions
A1: 异常清单
A2: 当前原始快照无数据质量异常；截止日外回款属于口径排除，见 checklist。脏数据规则由 tests/fixtures/dirty 覆盖。
A4: source | B4: line | C4: key | D4: kind | E4: detail | F4: classification | G4: blocking
D5: 当前样本无异常 | G5: 否

Sheet raw_order_lines
A1: order_id | B1: line_no | C1: customer_id | D1: order_date | E1: product_id | F1: unit | G1: ordered_qty | H1: delivered_qty | I1: returned_qty | J1: unit_price | K1: delivery_note | L1: is_simulated
A2: SIM-20260901-C001 | B2: 1 | C2: C001 | D2: 46266 | E2: P012 | F2: 公斤 | G2: 4.1 | H2: 4.1 | I2: 0 | J2: 4.6 | K2: 正常交付 | L2: true
A3: SIM-20260901-C001 | B3: 2 | C3: C001 | D3: 46266 | E3: P005 | F3: 公斤 | G3: 3.3 | H3: 3.3 | I3: 0 | J3: 2.7 | K3: 正常交付 | L3: true
A4: SIM-20260901-C001 | B4: 3 | C4: C001 | D4: 46266 | E4: P002 | F4: 公斤 | G4: 2.6 | H4: 2.6 | I4: 0 | J4: 2.3 | K4: 正常交付 | L4: true
A5: SIM-20260901-C001 | B5: 4 | C5: C001 | D5: 46266 | E5: P004 | F5: 公斤 | G5: 3 | H5: 3 | I5: 0 | J5: 2.3 | K5: 正常交付 | L5: true
A6: SIM-20260901-C001 | B6: 5 | C6: C001 | D6: 46266 | E6: P016 | F6: 公斤 | G6: 3 | H6: 3 | I6: 0 | J6: 10.1 | K6: 正常交付 | L6: true
A7: SIM-20260901-C001 | B7: 6 | C7: C001 | D7: 46266 | E7: P015 | F7: 公斤 | G7: 0.5 | H7: 0.5 | I7: 0 | J7: 7.3 | K7: 正常交付 | L7: true
A8: SIM-20260901-C001 | B8: 7 | C8: C001 | D8: 46266 | E8: P019 | F8: 桶 | G8: 1 | H8: 1 | I8: 0 | J8: 71 | K8: 正常交付 | L8: true
A9: SIM-20260901-C001 | B9: 8 | C9: C001 | D9: 46266 | E9: P018 | F9: 袋 | G9: 1 | H9: 1 | I9: 0 | J9: 111 | K9: 正常交付 | L9: true
A10: SIM-20260901-C002 | B10: 1 | C10: C002 | D10: 46266 | E10: P011 | F10: 公斤 | G10: 4.5 | H10: 4.5 | I10: 0 | J10: 4.4 | K10: 正常交付 | L10: true
A11: SIM-20260901-C002 | B11: 2 | C11: C002 | D11: 46266 | E11: P001 | F11: 公斤 | G11: 4.5 | H11: 4.5 | I11: 0 | J11: 3.3 | K11: 正常交付 | L11: true
A12: SIM-20260901-C002 | B12: 3 | C12: C002 | D12: 46266 | E12: P006 | F12: 公斤 | G12: 9 | H12: 9 | I12: 0 | J12: 4.6 | K12: 正常交付 | L12: true
A13: SIM-20260901-C002 | B13: 4 | C13: C002 | D13: 46266 | E13: P013 | F13: 公斤 | G13: 4.5 | H13: 4.5 | I13: 0 | J13: 6.3 | K13: 正常交付 | L13: true
... A967: SIM-20260930-C006 | B967: 6 | C967: C006 | D967: 46295 | E967: P001 | F967: 公斤 | G967: 5.5 | H967: 5.5 | I967: 0 | J967: 3.1 | K967: 正常交付 | L967: true

Sheet dim_products
A1: product_id | B1: product_name | C1: specification | D1: unit | E1: category | F1: simulated_price_min | G1: simulated_price_max | H1: is_simulated
A2: P001 | B2: 土豆 | C2: 散装鲜菜 | D2: 公斤 | E2: 根茎菜 | F2: 2.8 | G2: 4 | H2: true
A3: P002 | B3: 白萝卜 | C3: 散装鲜菜 | D3: 公斤 | E3: 根茎菜 | F3: 2 | G3: 3.2 | H3: true
A4: P003 | B4: 包菜 | C4: 散装鲜菜 | D4: 公斤 | E4: 甘蓝菜 | F4: 2.6 | G4: 3.8 | H4: true
A5: P004 | B5: 冬瓜 | C5: 散装鲜菜 | D5: 公斤 | E5: 瓜菜 | F5: 1.8 | G5: 3 | H5: true
A6: P005 | B6: 南瓜 | C6: 散装鲜菜 | D6: 公斤 | E6: 瓜菜 | F6: 2.4 | G6: 3.6 | H6: true
A7: P006 | B7: 茄子 | C7: 散装鲜菜 | D7: 公斤 | E7: 茄果菜 | F7: 3.8 | G7: 5.8 | H7: true
A8: P007 | B8: 青椒 | C8: 散装鲜菜 | D8: 公斤 | E8: 茄果菜 | F8: 4 | G8: 6.5 | H8: true
A9: P008 | B9: 黄瓜 | C9: 散装鲜菜 | D9: 公斤 | E9: 瓜菜 | F9: 3.2 | G9: 5.2 | H9: true
A10: P009 | B10: 西红柿 | C10: 散装鲜菜 | D10: 公斤 | E10: 茄果菜 | F10: 4 | G10: 6 | H10: true
A11: P010 | B11: 空心菜 | C11: 散装鲜菜 | D11: 公斤 | E11: 叶菜 | F11: 3.6 | G11: 5.8 | H11: true
A12: P011 | B12: 红薯叶 | C12: 散装鲜菜 | D12: 公斤 | E12: 叶菜 | F12: 3.6 | G12: 5.6 | H12: true
A13: P012 | B13: 小白菜 | C13: 散装鲜菜 | D13: 公斤 | E13: 叶菜 | F13: 3.8 | G13: 6 | H13: true
... A21: P020 | B21: 大豆油 | C21: 5升/桶普通大豆油 | D21: 桶 | E21: 食用油 | F21: 54 | G21: 62 | H21: true

Sheet dim_customers
A1: customer_id | B1: customer_name | C1: customer_type | D1: service_area | E1: meal_scale_assumption | F1: delivery_schedule | G1: settlement_cycle | H1: payment_due_date | I1: is_simulated
A2: C001 | B2: 模拟_榕树下粉面店 | C2: 粉面早餐店 | D2: 镇区 | E2: 70—100人次/日 | F2: 每周一至六 | G2: 自然月 | H2: 46305 | I2: true
A3: C002 | B3: 模拟_桥头家常菜馆 | C3: 家常菜馆 | D3: 镇区 | E3: 60—100人次/日 | F3: 每周二至日 | G3: 自然月 | H3: 46305 | I3: true
A4: C003 | B4: 模拟_兴街快餐店 | C4: 快餐店 | D4: 镇区 | E4: 100—160人次/日 | F4: 每周一至六 | G4: 自然月 | H4: 46305 | I4: true
A5: C004 | B5: 模拟_田畔饭店 | C5: 乡村饭店 | D5: 周边村庄 | E5: 平日40—60/周末80—120人次 | F5: 每周二四六 | G5: 自然月 | H5: 46305 | I5: true
A6: C005 | B6: 模拟_青禾小学食堂 | C6: 学校食堂 | D6: 镇区 | E6: 240人午餐/供餐日 | F6: 教学日 | G6: 自然月 | H6: 46305 | I6: true
A7: C006 | B7: 模拟_溪桥医院食堂 | C7: 医院食堂 | D7: 镇区 | E7: 约180人午餐/日 | F7: 每日配送 | G7: 自然月 | H7: 46305 | I7: true

Sheet fact_payments
A1: payment_id | B1: order_id | C1: payment_date | D1: amount | E1: receipt_id | F1: allocation_rule | G1: is_simulated
A2: SIM-P0001 | B2: SIM-20260901-C002 | C2: 46295 | D2: 598.22 | E2: SIM-R0001 | F2: 模拟确认：按订单日期及编号先后分配 | G2: true
A3: SIM-P0002 | B3: SIM-20260902-C002 | C3: 46295 | D3: 94.5 | E3: SIM-R0001 | F3: 模拟确认：按订单日期及编号先后分配 | G3: true
A4: SIM-P0003 | B4: SIM-20260903-C002 | C4: 46295 | D4: 138 | E4: SIM-R0001 | F4: 模拟确认：按订单日期及编号先后分配 | G4: true
A5: SIM-P0004 | B5: SIM-20260904-C002 | C5: 46295 | D5: 155.78 | E5: SIM-R0001 | F5: 模拟确认：按订单日期及编号先后分配 | G5: true
A6: SIM-P0005 | B6: SIM-20260905-C002 | C6: 46295 | D6: 13.5 | E6: SIM-R0001 | F6: 模拟确认：按订单日期及编号先后分配 | G6: true
A7: SIM-P0006 | B7: SIM-20260901-C005 | C7: 46295 | D7: 1212.68 | E7: SIM-R0002 | F7: 模拟确认：按订单日期及编号先后分配 | G7: true
A8: SIM-P0007 | B8: SIM-20260902-C005 | C8: 46295 | D8: 253.19 | E8: SIM-R0002 | F8: 模拟确认：按订单日期及编号先后分配 | G8: true
A9: SIM-P0008 | B9: SIM-20260903-C005 | C9: 46295 | D9: 375.73 | E9: SIM-R0002 | F9: 模拟确认：按订单日期及编号先后分配 | G9: true
A10: SIM-P0009 | B10: SIM-20260904-C005 | C10: 46295 | D10: 269.26 | E10: SIM-R0002 | F10: 模拟确认：按订单日期及编号先后分配 | G10: true
A11: SIM-P0010 | B11: SIM-20260907-C005 | C11: 46295 | D11: 357 | E11: SIM-R0002 | F11: 模拟确认：按订单日期及编号先后分配 | G11: true
A12: SIM-P0011 | B12: SIM-20260908-C005 | C12: 46295 | D12: 1039.42 | E12: SIM-R0002 | F12: 模拟确认：按订单日期及编号先后分配 | G12: true
A13: SIM-P0012 | B13: SIM-20260909-C005 | C13: 46295 | D13: 411.04 | E13: SIM-R0002 | F13: 模拟确认：按订单日期及编号先后分配 | G13: true
... A101: SIM-P0100 | B101: SIM-20260929-C004 | C101: 46301 | D101: 230 | E101: SIM-R0007 | F101: 模拟确认：按订单日期及编号先后分配 | G101: true

Sheet fact_receipts
A1: receipt_id | B1: customer_id | C1: payment_date | D1: amount | E1: payment_method | F1: settlement_month | G1: memo | H1: is_simulated
A2: SIM-R0001 | B2: C002 | C2: 46295 | D2: 1000 | E2: 微信转账 | F2: 2026-09 | G2: 模拟9月月结货款 | H2: true
A3: SIM-R0002 | B3: C005 | C3: 46295 | D3: 5000 | E3: 银行转账 | F3: 2026-09 | G3: 模拟9月月结货款 | H3: true
A4: SIM-R0003 | B4: C001 | C4: 46297 | D4: 2765.55 | E4: 微信转账 | F4: 2026-09 | G4: 模拟9月月结货款 | H4: true
A5: SIM-R0004 | B5: C003 | C5: 46299 | D5: 3000 | E5: 银行转账 | F5: 2026-09 | G5: 模拟9月月结货款 | H5: true
A6: SIM-R0005 | B6: C002 | C6: 46300 | D6: 5594.59 | E6: 银行转账 | F6: 2026-09 | G6: 模拟9月月结货款 | H6: true
A7: SIM-R0006 | B7: C006 | C7: 46300 | D7: 5000 | E7: 银行转账 | F7: 2026-09 | G7: 模拟9月月结货款 | H7: true
A8: SIM-R0007 | B8: C004 | C8: 46301 | D8: 3894.01 | E8: 微信转账 | F8: 2026-09 | G8: 模拟9月月结货款 | H8: true
